[2025-03-10T19:02:22.079+0000] {local_task_job_runner.py:120} INFO - ::group::Pre task execution logs
[2025-03-10T19:02:22.109+0000] {taskinstance.py:2073} INFO - Dependencies all met for dep_context=non-requeueable deps ti=<TaskInstance: sales_pipeline.ingest_erp_data manual__2025-03-10T19:00:47.481758+00:00 [queued]>
[2025-03-10T19:02:22.120+0000] {taskinstance.py:2073} INFO - Dependencies all met for dep_context=requeueable deps ti=<TaskInstance: sales_pipeline.ingest_erp_data manual__2025-03-10T19:00:47.481758+00:00 [queued]>
[2025-03-10T19:02:22.120+0000] {taskinstance.py:2303} INFO - Starting attempt 2 of 2
[2025-03-10T19:02:22.138+0000] {taskinstance.py:2327} INFO - Executing <Task(PythonOperator): ingest_erp_data> on 2025-03-10 19:00:47.481758+00:00
[2025-03-10T19:02:22.146+0000] {warnings.py:110} WARNING - /home/***/.local/lib/python3.12/site-packages/***/task/task_runner/standard_task_runner.py:61: DeprecationWarning: This process (pid=102) is multi-threaded, use of fork() may lead to deadlocks in the child.
  pid = os.fork()

[2025-03-10T19:02:22.147+0000] {standard_task_runner.py:63} INFO - Started process 107 to run task
[2025-03-10T19:02:22.148+0000] {standard_task_runner.py:90} INFO - Running: ['***', 'tasks', 'run', 'sales_pipeline', 'ingest_erp_data', 'manual__2025-03-10T19:00:47.481758+00:00', '--job-id', '29', '--raw', '--subdir', 'DAGS_FOLDER/pipeline.py', '--cfg-path', '/tmp/tmp9g4obhbh']
[2025-03-10T19:02:22.150+0000] {standard_task_runner.py:91} INFO - Job 29: Subtask ingest_erp_data
[2025-03-10T19:02:22.191+0000] {task_command.py:426} INFO - Running <TaskInstance: sales_pipeline.ingest_erp_data manual__2025-03-10T19:00:47.481758+00:00 [running]> on host e9482cc19388
[2025-03-10T19:02:22.280+0000] {taskinstance.py:2644} INFO - Exporting env vars: AIRFLOW_CTX_DAG_OWNER='Mahmoud' AIRFLOW_CTX_DAG_ID='sales_pipeline' AIRFLOW_CTX_TASK_ID='ingest_erp_data' AIRFLOW_CTX_EXECUTION_DATE='2025-03-10T19:00:47.481758+00:00' AIRFLOW_CTX_TRY_NUMBER='2' AIRFLOW_CTX_DAG_RUN_ID='manual__2025-03-10T19:00:47.481758+00:00'
[2025-03-10T19:02:22.281+0000] {taskinstance.py:430} INFO - ::endgroup::
[2025-03-10T19:02:22.365+0000] {warnings.py:110} WARNING - /home/***/.local/lib/python3.12/site-packages/snowflake/connector/options.py:108: UserWarning: You have an incompatible version of 'pyarrow' installed (19.0.1), please install a version that adheres to: 'pyarrow<19.0.0; extra == "pandas"'
  warn_incompatible_dep(

[2025-03-10T19:02:22.476+0000] {connection.py:423} INFO - Snowflake Connector for Python Version: 3.14.0, Python Version: 3.12.2, Platform: Linux-6.11.0-19-generic-x86_64-with-glibc2.36
[2025-03-10T19:02:22.477+0000] {connection.py:1226} INFO - Connecting to GLOBAL Snowflake domain
[2025-03-10T19:02:22.477+0000] {connection.py:1315} INFO - This connection is in OCSP Fail Open Mode. TLS Certificates would be checked for validity and revocation status. Any other Certificate Revocation related exceptions or OCSP Responder failures would be disregarded in favor of connectivity.
[2025-03-10T19:02:23.159+0000] {snowflake_utilz.py:13} INFO - Connected to snowflake successfully
[2025-03-10T19:02:23.160+0000] {snowflake_utilz.py:29} ERROR - Error while connecting to PostgreSQL: (psycopg2.OperationalError) connection to server at "172.23.0.2", port 5432 failed: Connection refused
	Is the server running on that host and accepting TCP/IP connections?

(Background on this error at: https://sqlalche.me/e/14/e3q8)
[2025-03-10T19:02:23.161+0000] {pipeline.py:111} INFO - 📥 Ingesting ERP data...
[2025-03-10T19:02:23.161+0000] {pipeline.py:114} ERROR - ❌ Database connection failed! Cannot ingest ERP data.
[2025-03-10T19:02:23.161+0000] {python.py:237} INFO - Done. Returned value was: None
[2025-03-10T19:02:23.162+0000] {taskinstance.py:441} INFO - ::group::Post task execution logs
[2025-03-10T19:02:23.262+0000] {taskinstance.py:1205} INFO - Marking task as SUCCESS. dag_id=sales_pipeline, task_id=ingest_erp_data, execution_date=20250310T190047, start_date=20250310T190222, end_date=20250310T190223
[2025-03-10T19:02:23.324+0000] {local_task_job_runner.py:240} INFO - Task exited with return code 0
[2025-03-10T19:02:23.342+0000] {taskinstance.py:3482} INFO - 0 downstream tasks scheduled from follow-on schedule check
[2025-03-10T19:02:23.343+0000] {local_task_job_runner.py:222} INFO - ::endgroup::
