[2025-03-11T11:52:27.310+0000] {local_task_job_runner.py:120} INFO - ::group::Pre task execution logs
[2025-03-11T11:52:27.332+0000] {taskinstance.py:2073} INFO - Dependencies all met for dep_context=non-requeueable deps ti=<TaskInstance: sales_pipeline.dbt_test_connection manual__2025-03-11T11:50:24.626163+00:00 [queued]>
[2025-03-11T11:52:27.341+0000] {taskinstance.py:2073} INFO - Dependencies all met for dep_context=requeueable deps ti=<TaskInstance: sales_pipeline.dbt_test_connection manual__2025-03-11T11:50:24.626163+00:00 [queued]>
[2025-03-11T11:52:27.341+0000] {taskinstance.py:2303} INFO - Starting attempt 2 of 2
[2025-03-11T11:52:27.358+0000] {taskinstance.py:2327} INFO - Executing <Task(BashOperator): dbt_test_connection> on 2025-03-11 11:50:24.626163+00:00
[2025-03-11T11:52:27.369+0000] {warnings.py:110} WARNING - /home/***/.local/lib/python3.12/site-packages/***/task/task_runner/standard_task_runner.py:61: DeprecationWarning: This process (pid=150) is multi-threaded, use of fork() may lead to deadlocks in the child.
  pid = os.fork()

[2025-03-11T11:52:27.371+0000] {standard_task_runner.py:63} INFO - Started process 152 to run task
[2025-03-11T11:52:27.371+0000] {standard_task_runner.py:90} INFO - Running: ['***', 'tasks', 'run', 'sales_pipeline', 'dbt_test_connection', 'manual__2025-03-11T11:50:24.626163+00:00', '--job-id', '103', '--raw', '--subdir', 'DAGS_FOLDER/pipeline.py', '--cfg-path', '/tmp/tmprm_30qsb']
[2025-03-11T11:52:27.374+0000] {standard_task_runner.py:91} INFO - Job 103: Subtask dbt_test_connection
[2025-03-11T11:52:27.418+0000] {task_command.py:426} INFO - Running <TaskInstance: sales_pipeline.dbt_test_connection manual__2025-03-11T11:50:24.626163+00:00 [running]> on host 2b35ac7f54da
[2025-03-11T11:52:27.509+0000] {taskinstance.py:2644} INFO - Exporting env vars: AIRFLOW_CTX_DAG_OWNER='Mahmoud' AIRFLOW_CTX_DAG_ID='sales_pipeline' AIRFLOW_CTX_TASK_ID='dbt_test_connection' AIRFLOW_CTX_EXECUTION_DATE='2025-03-11T11:50:24.626163+00:00' AIRFLOW_CTX_TRY_NUMBER='2' AIRFLOW_CTX_DAG_RUN_ID='manual__2025-03-11T11:50:24.626163+00:00'
[2025-03-11T11:52:27.510+0000] {taskinstance.py:430} INFO - ::endgroup::
[2025-03-11T11:52:27.527+0000] {subprocess.py:63} INFO - Tmp dir root location: /tmp
[2025-03-11T11:52:27.527+0000] {subprocess.py:75} INFO - Running command: ['/usr/bin/bash', '-c', 'dbt test --profiles-dir /opt/***/dbt --project-dir /opt/***/dbt/sales']
[2025-03-11T11:52:27.544+0000] {subprocess.py:86} INFO - Output:
[2025-03-11T11:52:30.531+0000] {subprocess.py:97} INFO - Command exited with return code 2
[2025-03-11T11:52:30.532+0000] {taskinstance.py:441} INFO - ::group::Post task execution logs
[2025-03-11T11:52:30.543+0000] {taskinstance.py:2890} ERROR - Task failed with exception
Traceback (most recent call last):
  File "/home/airflow/.local/lib/python3.12/site-packages/airflow/models/taskinstance.py", line 465, in _execute_task
    result = _execute_callable(context=context, **execute_callable_kwargs)
             ^^^^^^^^^^^^^^^^^^^^^^^^^^^^^^^^^^^^^^^^^^^^^^^^^^^^^^^^^^^^^
  File "/home/airflow/.local/lib/python3.12/site-packages/airflow/models/taskinstance.py", line 432, in _execute_callable
    return execute_callable(context=context, **execute_callable_kwargs)
           ^^^^^^^^^^^^^^^^^^^^^^^^^^^^^^^^^^^^^^^^^^^^^^^^^^^^^^^^^^^^
  File "/home/airflow/.local/lib/python3.12/site-packages/airflow/models/baseoperator.py", line 400, in wrapper
    return func(self, *args, **kwargs)
           ^^^^^^^^^^^^^^^^^^^^^^^^^^^
  File "/home/airflow/.local/lib/python3.12/site-packages/airflow/operators/bash.py", line 243, in execute
    raise AirflowException(
airflow.exceptions.AirflowException: Bash command failed. The command returned a non-zero exit code 2.
[2025-03-11T11:52:30.547+0000] {taskinstance.py:1205} INFO - Marking task as FAILED. dag_id=sales_pipeline, task_id=dbt_test_connection, execution_date=20250311T115024, start_date=20250311T115227, end_date=20250311T115230
[2025-03-11T11:52:30.561+0000] {standard_task_runner.py:110} ERROR - Failed to execute job 103 for task dbt_test_connection (Bash command failed. The command returned a non-zero exit code 2.; 152)
[2025-03-11T11:52:30.595+0000] {local_task_job_runner.py:240} INFO - Task exited with return code 1
[2025-03-11T11:52:30.614+0000] {taskinstance.py:3482} INFO - 0 downstream tasks scheduled from follow-on schedule check
[2025-03-11T11:52:30.615+0000] {local_task_job_runner.py:222} INFO - ::endgroup::
