[2025-03-13T11:30:07.615+0000] {local_task_job_runner.py:120} INFO - ::group::Pre task execution logs
[2025-03-13T11:30:07.640+0000] {taskinstance.py:2073} INFO - Dependencies all met for dep_context=non-requeueable deps ti=<TaskInstance: sales_pipeline.dbt_test_connection scheduled__2025-03-13T11:15:00+00:00 [queued]>
[2025-03-13T11:30:07.650+0000] {taskinstance.py:2073} INFO - Dependencies all met for dep_context=requeueable deps ti=<TaskInstance: sales_pipeline.dbt_test_connection scheduled__2025-03-13T11:15:00+00:00 [queued]>
[2025-03-13T11:30:07.651+0000] {taskinstance.py:2303} INFO - Starting attempt 1 of 1
[2025-03-13T11:30:07.663+0000] {taskinstance.py:2327} INFO - Executing <Task(BashOperator): dbt_test_connection> on 2025-03-13 11:15:00+00:00
[2025-03-13T11:30:07.672+0000] {warnings.py:110} WARNING - /home/***/.local/lib/python3.12/site-packages/***/task/task_runner/standard_task_runner.py:61: DeprecationWarning: This process (pid=1249) is multi-threaded, use of fork() may lead to deadlocks in the child.
  pid = os.fork()

[2025-03-13T11:30:07.674+0000] {standard_task_runner.py:63} INFO - Started process 1251 to run task
[2025-03-13T11:30:07.674+0000] {standard_task_runner.py:90} INFO - Running: ['***', 'tasks', 'run', 'sales_pipeline', 'dbt_test_connection', 'scheduled__2025-03-13T11:15:00+00:00', '--job-id', '160', '--raw', '--subdir', 'DAGS_FOLDER/pipeline.py', '--cfg-path', '/tmp/tmpp4p40xoz']
[2025-03-13T11:30:07.676+0000] {standard_task_runner.py:91} INFO - Job 160: Subtask dbt_test_connection
[2025-03-13T11:30:07.724+0000] {task_command.py:426} INFO - Running <TaskInstance: sales_pipeline.dbt_test_connection scheduled__2025-03-13T11:15:00+00:00 [running]> on host 2b35ac7f54da
[2025-03-13T11:30:07.825+0000] {taskinstance.py:2644} INFO - Exporting env vars: AIRFLOW_CTX_DAG_OWNER='Mahmoud' AIRFLOW_CTX_DAG_ID='sales_pipeline' AIRFLOW_CTX_TASK_ID='dbt_test_connection' AIRFLOW_CTX_EXECUTION_DATE='2025-03-13T11:15:00+00:00' AIRFLOW_CTX_TRY_NUMBER='1' AIRFLOW_CTX_DAG_RUN_ID='scheduled__2025-03-13T11:15:00+00:00'
[2025-03-13T11:30:07.826+0000] {taskinstance.py:430} INFO - ::endgroup::
[2025-03-13T11:30:07.842+0000] {subprocess.py:63} INFO - Tmp dir root location: /tmp
[2025-03-13T11:30:07.843+0000] {subprocess.py:75} INFO - Running command: ['/usr/bin/bash', '-c', 'dbt debug --profiles-dir /opt/***/dbt --project-dir /opt/***/dbt/sales']
[2025-03-13T11:30:07.861+0000] {subprocess.py:86} INFO - Output:
[2025-03-13T11:30:10.546+0000] {subprocess.py:93} INFO - [0m11:30:10  Running with dbt=1.9.3
[2025-03-13T11:30:10.624+0000] {subprocess.py:93} INFO - [0m11:30:10  dbt version: 1.9.3
[2025-03-13T11:30:10.625+0000] {subprocess.py:93} INFO - [0m11:30:10  python version: 3.12.2
[2025-03-13T11:30:10.626+0000] {subprocess.py:93} INFO - [0m11:30:10  python path: /home/***/.local/bin/python
[2025-03-13T11:30:10.626+0000] {subprocess.py:93} INFO - [0m11:30:10  os info: Linux-6.11.0-19-generic-x86_64-with-glibc2.36
[2025-03-13T11:30:11.255+0000] {subprocess.py:93} INFO - /home/***/.local/lib/python3.12/site-packages/snowflake/connector/options.py:108: UserWarning: You have an incompatible version of 'pyarrow' installed (19.0.1), please install a version that adheres to: 'pyarrow<19.0.0; extra == "pandas"'
[2025-03-13T11:30:11.255+0000] {subprocess.py:93} INFO -   warn_incompatible_dep(
[2025-03-13T11:30:11.641+0000] {subprocess.py:93} INFO - [0m11:30:11  Using profiles dir at /opt/***/dbt
[2025-03-13T11:30:11.641+0000] {subprocess.py:93} INFO - [0m11:30:11  Using profiles.yml file at /opt/***/dbt/profiles.yml
[2025-03-13T11:30:11.642+0000] {subprocess.py:93} INFO - [0m11:30:11  Using dbt_project.yml file at /opt/***/dbt/sales/dbt_project.yml
[2025-03-13T11:30:11.643+0000] {subprocess.py:93} INFO - [0m11:30:11  adapter type: snowflake
[2025-03-13T11:30:11.644+0000] {subprocess.py:93} INFO - [0m11:30:11  adapter version: 1.9.2
[2025-03-13T11:30:11.780+0000] {subprocess.py:93} INFO - [0m11:30:11  Configuration:
[2025-03-13T11:30:11.781+0000] {subprocess.py:93} INFO - [0m11:30:11    profiles.yml file [[32mOK found and valid[0m]
[2025-03-13T11:30:11.782+0000] {subprocess.py:93} INFO - [0m11:30:11    dbt_project.yml file [[32mOK found and valid[0m]
[2025-03-13T11:30:11.782+0000] {subprocess.py:93} INFO - [0m11:30:11  Required dependencies:
[2025-03-13T11:30:11.787+0000] {subprocess.py:93} INFO - [0m11:30:11   - git [[32mOK found[0m]
[2025-03-13T11:30:11.787+0000] {subprocess.py:93} INFO - 
[2025-03-13T11:30:11.787+0000] {subprocess.py:93} INFO - [0m11:30:11  Connection:
[2025-03-13T11:30:11.788+0000] {subprocess.py:93} INFO - [0m11:30:11    account: lxdzptn-eu09470
[2025-03-13T11:30:11.788+0000] {subprocess.py:93} INFO - [0m11:30:11    user: momod
[2025-03-13T11:30:11.789+0000] {subprocess.py:93} INFO - [0m11:30:11    database: sales
[2025-03-13T11:30:11.789+0000] {subprocess.py:93} INFO - [0m11:30:11    warehouse: sales_WH
[2025-03-13T11:30:11.790+0000] {subprocess.py:93} INFO - [0m11:30:11    role: ACCOUNTADMIN
[2025-03-13T11:30:11.790+0000] {subprocess.py:93} INFO - [0m11:30:11    schema: bronze_layer
[2025-03-13T11:30:11.791+0000] {subprocess.py:93} INFO - [0m11:30:11    authenticator: None
[2025-03-13T11:30:11.791+0000] {subprocess.py:93} INFO - [0m11:30:11    oauth_client_id: None
[2025-03-13T11:30:11.792+0000] {subprocess.py:93} INFO - [0m11:30:11    query_tag: None
[2025-03-13T11:30:11.792+0000] {subprocess.py:93} INFO - [0m11:30:11    client_session_keep_alive: False
[2025-03-13T11:30:11.793+0000] {subprocess.py:93} INFO - [0m11:30:11    host: None
[2025-03-13T11:30:11.794+0000] {subprocess.py:93} INFO - [0m11:30:11    port: None
[2025-03-13T11:30:11.794+0000] {subprocess.py:93} INFO - [0m11:30:11    proxy_host: None
[2025-03-13T11:30:11.795+0000] {subprocess.py:93} INFO - [0m11:30:11    proxy_port: None
[2025-03-13T11:30:11.795+0000] {subprocess.py:93} INFO - [0m11:30:11    protocol: None
[2025-03-13T11:30:11.796+0000] {subprocess.py:93} INFO - [0m11:30:11    connect_retries: 1
[2025-03-13T11:30:11.796+0000] {subprocess.py:93} INFO - [0m11:30:11    connect_timeout: None
[2025-03-13T11:30:11.797+0000] {subprocess.py:93} INFO - [0m11:30:11    retry_on_database_errors: False
[2025-03-13T11:30:11.797+0000] {subprocess.py:93} INFO - [0m11:30:11    retry_all: False
[2025-03-13T11:30:11.798+0000] {subprocess.py:93} INFO - [0m11:30:11    insecure_mode: False
[2025-03-13T11:30:11.798+0000] {subprocess.py:93} INFO - [0m11:30:11    reuse_connections: True
[2025-03-13T11:30:11.799+0000] {subprocess.py:93} INFO - [0m11:30:11  Registered adapter: snowflake=1.9.2
[2025-03-13T11:30:12.558+0000] {subprocess.py:93} INFO - [0m11:30:12    Connection test: [[32mOK connection ok[0m]
[2025-03-13T11:30:12.559+0000] {subprocess.py:93} INFO - 
[2025-03-13T11:30:12.559+0000] {subprocess.py:93} INFO - [0m11:30:12  [32mAll checks passed![0m
[2025-03-13T11:30:13.778+0000] {subprocess.py:97} INFO - Command exited with return code 0
[2025-03-13T11:30:13.779+0000] {taskinstance.py:441} INFO - ::group::Post task execution logs
[2025-03-13T11:30:13.803+0000] {taskinstance.py:1205} INFO - Marking task as SUCCESS. dag_id=sales_pipeline, task_id=dbt_test_connection, execution_date=20250313T111500, start_date=20250313T113007, end_date=20250313T113013
[2025-03-13T11:30:13.825+0000] {local_task_job_runner.py:240} INFO - Task exited with return code 0
[2025-03-13T11:30:13.845+0000] {taskinstance.py:3482} INFO - 0 downstream tasks scheduled from follow-on schedule check
[2025-03-13T11:30:13.847+0000] {local_task_job_runner.py:222} INFO - ::endgroup::
