[2025-03-13T20:30:05.543+0000] {local_task_job_runner.py:120} INFO - ::group::Pre task execution logs
[2025-03-13T20:30:05.565+0000] {taskinstance.py:2073} INFO - Dependencies all met for dep_context=non-requeueable deps ti=<TaskInstance: sales_pipeline.ingest_data.ingest_erp_data scheduled__2025-03-13T20:15:00+00:00 [queued]>
[2025-03-13T20:30:05.573+0000] {taskinstance.py:2073} INFO - Dependencies all met for dep_context=requeueable deps ti=<TaskInstance: sales_pipeline.ingest_data.ingest_erp_data scheduled__2025-03-13T20:15:00+00:00 [queued]>
[2025-03-13T20:30:05.573+0000] {taskinstance.py:2303} INFO - Starting attempt 1 of 1
[2025-03-13T20:30:05.586+0000] {taskinstance.py:2327} INFO - Executing <Task(PythonOperator): ingest_data.ingest_erp_data> on 2025-03-13 20:15:00+00:00
[2025-03-13T20:30:05.597+0000] {warnings.py:110} WARNING - /home/***/.local/lib/python3.12/site-packages/***/task/task_runner/standard_task_runner.py:61: DeprecationWarning: This process (pid=974) is multi-threaded, use of fork() may lead to deadlocks in the child.
  pid = os.fork()

[2025-03-13T20:30:05.599+0000] {standard_task_runner.py:63} INFO - Started process 978 to run task
[2025-03-13T20:30:05.599+0000] {standard_task_runner.py:90} INFO - Running: ['***', 'tasks', 'run', 'sales_pipeline', 'ingest_data.ingest_erp_data', 'scheduled__2025-03-13T20:15:00+00:00', '--job-id', '200', '--raw', '--subdir', 'DAGS_FOLDER/pipeline.py', '--cfg-path', '/tmp/tmpt9vpvngs']
[2025-03-13T20:30:05.602+0000] {standard_task_runner.py:91} INFO - Job 200: Subtask ingest_data.ingest_erp_data
[2025-03-13T20:30:05.646+0000] {task_command.py:426} INFO - Running <TaskInstance: sales_pipeline.ingest_data.ingest_erp_data scheduled__2025-03-13T20:15:00+00:00 [running]> on host 2b35ac7f54da
[2025-03-13T20:30:05.732+0000] {taskinstance.py:2644} INFO - Exporting env vars: AIRFLOW_CTX_DAG_OWNER='Mahmoud' AIRFLOW_CTX_DAG_ID='sales_pipeline' AIRFLOW_CTX_TASK_ID='ingest_data.ingest_erp_data' AIRFLOW_CTX_EXECUTION_DATE='2025-03-13T20:15:00+00:00' AIRFLOW_CTX_TRY_NUMBER='1' AIRFLOW_CTX_DAG_RUN_ID='scheduled__2025-03-13T20:15:00+00:00'
[2025-03-13T20:30:05.733+0000] {taskinstance.py:430} INFO - ::endgroup::
[2025-03-13T20:30:05.745+0000] {pipeline.py:96} INFO - /opt/***/Source/source_crm
[2025-03-13T20:30:05.826+0000] {warnings.py:110} WARNING - /home/***/.local/lib/python3.12/site-packages/snowflake/connector/options.py:108: UserWarning: You have an incompatible version of 'pyarrow' installed (19.0.1), please install a version that adheres to: 'pyarrow<19.0.0; extra == "pandas"'
  warn_incompatible_dep(

[2025-03-13T20:30:05.934+0000] {connection.py:423} INFO - Snowflake Connector for Python Version: 3.14.0, Python Version: 3.12.2, Platform: Linux-6.11.0-19-generic-x86_64-with-glibc2.36
[2025-03-13T20:30:05.935+0000] {connection.py:1226} INFO - Connecting to GLOBAL Snowflake domain
[2025-03-13T20:30:05.935+0000] {connection.py:1315} INFO - This connection is in OCSP Fail Open Mode. TLS Certificates would be checked for validity and revocation status. Any other Certificate Revocation related exceptions or OCSP Responder failures would be disregarded in favor of connectivity.
[2025-03-13T20:30:06.593+0000] {snowflake_utilz.py:13} INFO - Connected to snowflake successfully
[2025-03-13T20:30:06.594+0000] {snowflake_utilz.py:29} ERROR - Error while connecting to PostgreSQL: (psycopg2.OperationalError) connection to server at "172.23.0.3", port 5432 failed: Connection refused
	Is the server running on that host and accepting TCP/IP connections?

(Background on this error at: https://sqlalche.me/e/14/e3q8)
[2025-03-13T20:30:06.595+0000] {pipeline.py:104} INFO - ðŸ“¥ Ingesting ERP data...
[2025-03-13T20:30:06.596+0000] {ingest_data.py:28} ERROR - Error ingesting data from CUST_AZ12.csv into erp_cust_az12: 'NoneType' object has no attribute 'execute'
[2025-03-13T20:30:06.596+0000] {ingest_data.py:28} ERROR - Error ingesting data from LOC_A101.csv into erp_loc_a101: 'NoneType' object has no attribute 'execute'
[2025-03-13T20:30:06.596+0000] {ingest_data.py:28} ERROR - Error ingesting data from PX_CAT_G1V2.csv into erp_px_cat_g1v2: 'NoneType' object has no attribute 'execute'
[2025-03-13T20:30:06.700+0000] {snowflake_utilz.py:35} INFO - connection is closed
[2025-03-13T20:30:06.700+0000] {connection.py:810} INFO - closed
[2025-03-13T20:30:06.781+0000] {connection.py:816} INFO - No async queries seem to be running, deleting session
[2025-03-13T20:30:06.864+0000] {snowflake_utilz.py:38} INFO - SQLAlchemy engine disposed
[2025-03-13T20:30:06.865+0000] {python.py:237} INFO - Done. Returned value was: None
[2025-03-13T20:30:06.865+0000] {taskinstance.py:441} INFO - ::group::Post task execution logs
[2025-03-13T20:30:06.875+0000] {taskinstance.py:1205} INFO - Marking task as SUCCESS. dag_id=sales_pipeline, task_id=ingest_data.ingest_erp_data, execution_date=20250313T201500, start_date=20250313T203005, end_date=20250313T203006
[2025-03-13T20:30:06.935+0000] {local_task_job_runner.py:240} INFO - Task exited with return code 0
[2025-03-13T20:30:06.963+0000] {taskinstance.py:3482} INFO - 0 downstream tasks scheduled from follow-on schedule check
[2025-03-13T20:30:06.964+0000] {local_task_job_runner.py:222} INFO - ::endgroup::
