[2025-03-10T19:10:05.047+0000] {local_task_job_runner.py:120} INFO - ::group::Pre task execution logs
[2025-03-10T19:10:05.079+0000] {taskinstance.py:2073} INFO - Dependencies all met for dep_context=non-requeueable deps ti=<TaskInstance: sales_pipeline.ingest_crm_data manual__2025-03-10T19:09:59.850896+00:00 [queued]>
[2025-03-10T19:10:05.093+0000] {taskinstance.py:2073} INFO - Dependencies all met for dep_context=requeueable deps ti=<TaskInstance: sales_pipeline.ingest_crm_data manual__2025-03-10T19:09:59.850896+00:00 [queued]>
[2025-03-10T19:10:05.094+0000] {taskinstance.py:2303} INFO - Starting attempt 1 of 1
[2025-03-10T19:10:05.111+0000] {taskinstance.py:2327} INFO - Executing <Task(PythonOperator): ingest_crm_data> on 2025-03-10 19:09:59.850896+00:00
[2025-03-10T19:10:05.123+0000] {warnings.py:110} WARNING - /home/***/.local/lib/python3.12/site-packages/***/task/task_runner/standard_task_runner.py:61: DeprecationWarning: This process (pid=61) is multi-threaded, use of fork() may lead to deadlocks in the child.
  pid = os.fork()

[2025-03-10T19:10:05.125+0000] {standard_task_runner.py:63} INFO - Started process 65 to run task
[2025-03-10T19:10:05.126+0000] {standard_task_runner.py:90} INFO - Running: ['***', 'tasks', 'run', 'sales_pipeline', 'ingest_crm_data', 'manual__2025-03-10T19:09:59.850896+00:00', '--job-id', '51', '--raw', '--subdir', 'DAGS_FOLDER/pipeline.py', '--cfg-path', '/tmp/tmp8jg1y8yr']
[2025-03-10T19:10:05.129+0000] {standard_task_runner.py:91} INFO - Job 51: Subtask ingest_crm_data
[2025-03-10T19:10:05.182+0000] {task_command.py:426} INFO - Running <TaskInstance: sales_pipeline.ingest_crm_data manual__2025-03-10T19:09:59.850896+00:00 [running]> on host e9482cc19388
[2025-03-10T19:10:05.301+0000] {taskinstance.py:2644} INFO - Exporting env vars: AIRFLOW_CTX_DAG_OWNER='Mahmoud' AIRFLOW_CTX_DAG_ID='sales_pipeline' AIRFLOW_CTX_TASK_ID='ingest_crm_data' AIRFLOW_CTX_EXECUTION_DATE='2025-03-10T19:09:59.850896+00:00' AIRFLOW_CTX_TRY_NUMBER='1' AIRFLOW_CTX_DAG_RUN_ID='manual__2025-03-10T19:09:59.850896+00:00'
[2025-03-10T19:10:05.302+0000] {taskinstance.py:430} INFO - ::endgroup::
[2025-03-10T19:10:05.415+0000] {warnings.py:110} WARNING - /home/***/.local/lib/python3.12/site-packages/snowflake/connector/options.py:108: UserWarning: You have an incompatible version of 'pyarrow' installed (19.0.1), please install a version that adheres to: 'pyarrow<19.0.0; extra == "pandas"'
  warn_incompatible_dep(

[2025-03-10T19:10:05.576+0000] {connection.py:423} INFO - Snowflake Connector for Python Version: 3.14.0, Python Version: 3.12.2, Platform: Linux-6.11.0-19-generic-x86_64-with-glibc2.36
[2025-03-10T19:10:05.577+0000] {connection.py:1226} INFO - Connecting to GLOBAL Snowflake domain
[2025-03-10T19:10:05.577+0000] {connection.py:1315} INFO - This connection is in OCSP Fail Open Mode. TLS Certificates would be checked for validity and revocation status. Any other Certificate Revocation related exceptions or OCSP Responder failures would be disregarded in favor of connectivity.
[2025-03-10T19:10:06.386+0000] {snowflake_utilz.py:13} INFO - Connected to snowflake successfully
[2025-03-10T19:10:06.392+0000] {snowflake_utilz.py:26} INFO - Connected to PostgreSQL database successfully
[2025-03-10T19:10:06.393+0000] {pipeline.py:81} INFO - ðŸ“¥ Ingesting CRM data...
[2025-03-10T19:10:06.394+0000] {ingest_data.py:15} INFO - Start ingesting cust_info.csv into crm_cust_info
[2025-03-10T19:10:06.395+0000] {ingest_data.py:28} ERROR - Error ingesting data from cust_info.csv into crm_cust_info: [Errno 2] No such file or directory: 'opt/***/Source/source_erp/cust_info.csv'
[2025-03-10T19:10:06.396+0000] {ingest_data.py:15} INFO - Start ingesting prd_info.csv into crm_prd_info
[2025-03-10T19:10:06.396+0000] {ingest_data.py:28} ERROR - Error ingesting data from prd_info.csv into crm_prd_info: [Errno 2] No such file or directory: 'opt/***/Source/source_erp/prd_info.csv'
[2025-03-10T19:10:06.397+0000] {ingest_data.py:15} INFO - Start ingesting sales_details.csv into crm_sales_details
[2025-03-10T19:10:06.398+0000] {ingest_data.py:28} ERROR - Error ingesting data from sales_details.csv into crm_sales_details: [Errno 2] No such file or directory: 'opt/***/Source/source_erp/sales_details.csv'
[2025-03-10T19:10:06.492+0000] {snowflake_utilz.py:35} INFO - connection is closed
[2025-03-10T19:10:06.493+0000] {connection.py:810} INFO - closed
[2025-03-10T19:10:06.564+0000] {connection.py:816} INFO - No async queries seem to be running, deleting session
[2025-03-10T19:10:06.648+0000] {snowflake_utilz.py:38} INFO - SQLAlchemy engine disposed
[2025-03-10T19:10:06.649+0000] {snowflake_utilz.py:35} INFO - connection is closed
[2025-03-10T19:10:06.649+0000] {snowflake_utilz.py:38} INFO - SQLAlchemy engine disposed
[2025-03-10T19:10:06.649+0000] {python.py:237} INFO - Done. Returned value was: None
[2025-03-10T19:10:06.650+0000] {taskinstance.py:441} INFO - ::group::Post task execution logs
[2025-03-10T19:10:06.660+0000] {taskinstance.py:1205} INFO - Marking task as SUCCESS. dag_id=sales_pipeline, task_id=ingest_crm_data, execution_date=20250310T190959, start_date=20250310T191005, end_date=20250310T191006
[2025-03-10T19:10:06.703+0000] {local_task_job_runner.py:240} INFO - Task exited with return code 0
[2025-03-10T19:10:06.720+0000] {taskinstance.py:3482} INFO - 0 downstream tasks scheduled from follow-on schedule check
[2025-03-10T19:10:06.722+0000] {local_task_job_runner.py:222} INFO - ::endgroup::
