[2025-03-11T18:15:10.515+0000] {local_task_job_runner.py:120} INFO - ::group::Pre task execution logs
[2025-03-11T18:15:10.539+0000] {taskinstance.py:2073} INFO - Dependencies all met for dep_context=non-requeueable deps ti=<TaskInstance: sales_pipeline.dbt_test_connection scheduled__2025-03-11T18:00:00+00:00 [queued]>
[2025-03-11T18:15:10.550+0000] {taskinstance.py:2073} INFO - Dependencies all met for dep_context=requeueable deps ti=<TaskInstance: sales_pipeline.dbt_test_connection scheduled__2025-03-11T18:00:00+00:00 [queued]>
[2025-03-11T18:15:10.550+0000] {taskinstance.py:2303} INFO - Starting attempt 1 of 1
[2025-03-11T18:15:10.564+0000] {taskinstance.py:2327} INFO - Executing <Task(BashOperator): dbt_test_connection> on 2025-03-11 18:00:00+00:00
[2025-03-11T18:15:10.575+0000] {warnings.py:110} WARNING - /home/***/.local/lib/python3.12/site-packages/***/task/task_runner/standard_task_runner.py:61: DeprecationWarning: This process (pid=441) is multi-threaded, use of fork() may lead to deadlocks in the child.
  pid = os.fork()

[2025-03-11T18:15:10.576+0000] {standard_task_runner.py:63} INFO - Started process 443 to run task
[2025-03-11T18:15:10.576+0000] {standard_task_runner.py:90} INFO - Running: ['***', 'tasks', 'run', 'sales_pipeline', 'dbt_test_connection', 'scheduled__2025-03-11T18:00:00+00:00', '--job-id', '141', '--raw', '--subdir', 'DAGS_FOLDER/pipeline.py', '--cfg-path', '/tmp/tmp6l38vnz8']
[2025-03-11T18:15:10.578+0000] {standard_task_runner.py:91} INFO - Job 141: Subtask dbt_test_connection
[2025-03-11T18:15:10.621+0000] {task_command.py:426} INFO - Running <TaskInstance: sales_pipeline.dbt_test_connection scheduled__2025-03-11T18:00:00+00:00 [running]> on host 2b35ac7f54da
[2025-03-11T18:15:10.714+0000] {taskinstance.py:2644} INFO - Exporting env vars: AIRFLOW_CTX_DAG_OWNER='Mahmoud' AIRFLOW_CTX_DAG_ID='sales_pipeline' AIRFLOW_CTX_TASK_ID='dbt_test_connection' AIRFLOW_CTX_EXECUTION_DATE='2025-03-11T18:00:00+00:00' AIRFLOW_CTX_TRY_NUMBER='1' AIRFLOW_CTX_DAG_RUN_ID='scheduled__2025-03-11T18:00:00+00:00'
[2025-03-11T18:15:10.716+0000] {taskinstance.py:430} INFO - ::endgroup::
[2025-03-11T18:15:10.731+0000] {subprocess.py:63} INFO - Tmp dir root location: /tmp
[2025-03-11T18:15:10.732+0000] {subprocess.py:75} INFO - Running command: ['/usr/bin/bash', '-c', 'dbt debug --profiles-dir /opt/***/dbt --project-dir /opt/***/dbt/sales']
[2025-03-11T18:15:10.754+0000] {subprocess.py:86} INFO - Output:
[2025-03-11T18:15:13.511+0000] {subprocess.py:93} INFO - [0m18:15:13  Running with dbt=1.9.3
[2025-03-11T18:15:13.588+0000] {subprocess.py:93} INFO - [0m18:15:13  dbt version: 1.9.3
[2025-03-11T18:15:13.589+0000] {subprocess.py:93} INFO - [0m18:15:13  python version: 3.12.2
[2025-03-11T18:15:13.589+0000] {subprocess.py:93} INFO - [0m18:15:13  python path: /home/***/.local/bin/python
[2025-03-11T18:15:13.589+0000] {subprocess.py:93} INFO - [0m18:15:13  os info: Linux-6.11.0-19-generic-x86_64-with-glibc2.36
[2025-03-11T18:15:14.111+0000] {subprocess.py:93} INFO - /home/***/.local/lib/python3.12/site-packages/snowflake/connector/options.py:108: UserWarning: You have an incompatible version of 'pyarrow' installed (19.0.1), please install a version that adheres to: 'pyarrow<19.0.0; extra == "pandas"'
[2025-03-11T18:15:14.112+0000] {subprocess.py:93} INFO -   warn_incompatible_dep(
[2025-03-11T18:15:14.427+0000] {subprocess.py:93} INFO - [0m18:15:14  Using profiles dir at /opt/***/dbt
[2025-03-11T18:15:14.428+0000] {subprocess.py:93} INFO - [0m18:15:14  Using profiles.yml file at /opt/***/dbt/profiles.yml
[2025-03-11T18:15:14.428+0000] {subprocess.py:93} INFO - [0m18:15:14  Using dbt_project.yml file at /opt/***/dbt/sales/dbt_project.yml
[2025-03-11T18:15:14.429+0000] {subprocess.py:93} INFO - [0m18:15:14  adapter type: snowflake
[2025-03-11T18:15:14.429+0000] {subprocess.py:93} INFO - [0m18:15:14  adapter version: 1.9.2
[2025-03-11T18:15:14.557+0000] {subprocess.py:93} INFO - [0m18:15:14  Configuration:
[2025-03-11T18:15:14.557+0000] {subprocess.py:93} INFO - [0m18:15:14    profiles.yml file [[32mOK found and valid[0m]
[2025-03-11T18:15:14.558+0000] {subprocess.py:93} INFO - [0m18:15:14    dbt_project.yml file [[32mOK found and valid[0m]
[2025-03-11T18:15:14.558+0000] {subprocess.py:93} INFO - [0m18:15:14  Required dependencies:
[2025-03-11T18:15:14.564+0000] {subprocess.py:93} INFO - [0m18:15:14   - git [[32mOK found[0m]
[2025-03-11T18:15:14.564+0000] {subprocess.py:93} INFO - 
[2025-03-11T18:15:14.565+0000] {subprocess.py:93} INFO - [0m18:15:14  Connection:
[2025-03-11T18:15:14.565+0000] {subprocess.py:93} INFO - [0m18:15:14    account: lxdzptn-eu09470
[2025-03-11T18:15:14.565+0000] {subprocess.py:93} INFO - [0m18:15:14    user: momod
[2025-03-11T18:15:14.566+0000] {subprocess.py:93} INFO - [0m18:15:14    database: sales
[2025-03-11T18:15:14.566+0000] {subprocess.py:93} INFO - [0m18:15:14    warehouse: COMPUTE_WH
[2025-03-11T18:15:14.567+0000] {subprocess.py:93} INFO - [0m18:15:14    role: ACCOUNTADMIN
[2025-03-11T18:15:14.567+0000] {subprocess.py:93} INFO - [0m18:15:14    schema: bronze_layer
[2025-03-11T18:15:14.567+0000] {subprocess.py:93} INFO - [0m18:15:14    authenticator: None
[2025-03-11T18:15:14.568+0000] {subprocess.py:93} INFO - [0m18:15:14    oauth_client_id: None
[2025-03-11T18:15:14.569+0000] {subprocess.py:93} INFO - [0m18:15:14    query_tag: None
[2025-03-11T18:15:14.569+0000] {subprocess.py:93} INFO - [0m18:15:14    client_session_keep_alive: False
[2025-03-11T18:15:14.570+0000] {subprocess.py:93} INFO - [0m18:15:14    host: None
[2025-03-11T18:15:14.570+0000] {subprocess.py:93} INFO - [0m18:15:14    port: None
[2025-03-11T18:15:14.571+0000] {subprocess.py:93} INFO - [0m18:15:14    proxy_host: None
[2025-03-11T18:15:14.571+0000] {subprocess.py:93} INFO - [0m18:15:14    proxy_port: None
[2025-03-11T18:15:14.572+0000] {subprocess.py:93} INFO - [0m18:15:14    protocol: None
[2025-03-11T18:15:14.572+0000] {subprocess.py:93} INFO - [0m18:15:14    connect_retries: 1
[2025-03-11T18:15:14.573+0000] {subprocess.py:93} INFO - [0m18:15:14    connect_timeout: None
[2025-03-11T18:15:14.573+0000] {subprocess.py:93} INFO - [0m18:15:14    retry_on_database_errors: False
[2025-03-11T18:15:14.573+0000] {subprocess.py:93} INFO - [0m18:15:14    retry_all: False
[2025-03-11T18:15:14.574+0000] {subprocess.py:93} INFO - [0m18:15:14    insecure_mode: False
[2025-03-11T18:15:14.574+0000] {subprocess.py:93} INFO - [0m18:15:14    reuse_connections: True
[2025-03-11T18:15:14.575+0000] {subprocess.py:93} INFO - [0m18:15:14  Registered adapter: snowflake=1.9.2
[2025-03-11T18:15:15.751+0000] {subprocess.py:93} INFO - [0m18:15:15    Connection test: [[32mOK connection ok[0m]
[2025-03-11T18:15:15.752+0000] {subprocess.py:93} INFO - 
[2025-03-11T18:15:15.752+0000] {subprocess.py:93} INFO - [0m18:15:15  [32mAll checks passed![0m
[2025-03-11T18:15:17.358+0000] {subprocess.py:97} INFO - Command exited with return code 0
[2025-03-11T18:15:17.360+0000] {taskinstance.py:441} INFO - ::group::Post task execution logs
[2025-03-11T18:15:17.389+0000] {taskinstance.py:1205} INFO - Marking task as SUCCESS. dag_id=sales_pipeline, task_id=dbt_test_connection, execution_date=20250311T180000, start_date=20250311T181510, end_date=20250311T181517
[2025-03-11T18:15:17.441+0000] {local_task_job_runner.py:240} INFO - Task exited with return code 0
[2025-03-11T18:15:17.460+0000] {taskinstance.py:3482} INFO - 0 downstream tasks scheduled from follow-on schedule check
[2025-03-11T18:15:17.462+0000] {local_task_job_runner.py:222} INFO - ::endgroup::
