[2025-03-11T18:30:01.299+0000] {local_task_job_runner.py:120} INFO - ::group::Pre task execution logs
[2025-03-11T18:30:01.326+0000] {taskinstance.py:2073} INFO - Dependencies all met for dep_context=non-requeueable deps ti=<TaskInstance: sales_pipeline.test_snowflake_connection scheduled__2025-03-11T18:15:00+00:00 [queued]>
[2025-03-11T18:30:01.332+0000] {taskinstance.py:2073} INFO - Dependencies all met for dep_context=requeueable deps ti=<TaskInstance: sales_pipeline.test_snowflake_connection scheduled__2025-03-11T18:15:00+00:00 [queued]>
[2025-03-11T18:30:01.333+0000] {taskinstance.py:2303} INFO - Starting attempt 1 of 1
[2025-03-11T18:30:01.348+0000] {taskinstance.py:2327} INFO - Executing <Task(PythonOperator): test_snowflake_connection> on 2025-03-11 18:15:00+00:00
[2025-03-11T18:30:01.358+0000] {warnings.py:110} WARNING - /home/***/.local/lib/python3.12/site-packages/***/task/task_runner/standard_task_runner.py:61: DeprecationWarning: This process (pid=456) is multi-threaded, use of fork() may lead to deadlocks in the child.
  pid = os.fork()

[2025-03-11T18:30:01.360+0000] {standard_task_runner.py:63} INFO - Started process 458 to run task
[2025-03-11T18:30:01.361+0000] {standard_task_runner.py:90} INFO - Running: ['***', 'tasks', 'run', 'sales_pipeline', 'test_snowflake_connection', 'scheduled__2025-03-11T18:15:00+00:00', '--job-id', '142', '--raw', '--subdir', 'DAGS_FOLDER/pipeline.py', '--cfg-path', '/tmp/tmpa_7au2i_']
[2025-03-11T18:30:01.362+0000] {standard_task_runner.py:91} INFO - Job 142: Subtask test_snowflake_connection
[2025-03-11T18:30:01.404+0000] {task_command.py:426} INFO - Running <TaskInstance: sales_pipeline.test_snowflake_connection scheduled__2025-03-11T18:15:00+00:00 [running]> on host 2b35ac7f54da
[2025-03-11T18:30:01.496+0000] {taskinstance.py:2644} INFO - Exporting env vars: AIRFLOW_CTX_DAG_OWNER='Mahmoud' AIRFLOW_CTX_DAG_ID='sales_pipeline' AIRFLOW_CTX_TASK_ID='test_snowflake_connection' AIRFLOW_CTX_EXECUTION_DATE='2025-03-11T18:15:00+00:00' AIRFLOW_CTX_TRY_NUMBER='1' AIRFLOW_CTX_DAG_RUN_ID='scheduled__2025-03-11T18:15:00+00:00'
[2025-03-11T18:30:01.497+0000] {taskinstance.py:430} INFO - ::endgroup::
[2025-03-11T18:30:01.592+0000] {warnings.py:110} WARNING - /home/***/.local/lib/python3.12/site-packages/snowflake/connector/options.py:108: UserWarning: You have an incompatible version of 'pyarrow' installed (19.0.1), please install a version that adheres to: 'pyarrow<19.0.0; extra == "pandas"'
  warn_incompatible_dep(

[2025-03-11T18:30:01.701+0000] {connection.py:423} INFO - Snowflake Connector for Python Version: 3.14.0, Python Version: 3.12.2, Platform: Linux-6.11.0-19-generic-x86_64-with-glibc2.36
[2025-03-11T18:30:01.702+0000] {connection.py:1226} INFO - Connecting to GLOBAL Snowflake domain
[2025-03-11T18:30:01.703+0000] {connection.py:1315} INFO - This connection is in OCSP Fail Open Mode. TLS Certificates would be checked for validity and revocation status. Any other Certificate Revocation related exceptions or OCSP Responder failures would be disregarded in favor of connectivity.
[2025-03-11T18:30:02.987+0000] {snowflake_utilz.py:13} INFO - Connected to snowflake successfully
[2025-03-11T18:30:02.987+0000] {pipeline.py:53} INFO - âœ… Snowflake connection successful!
[2025-03-11T18:30:03.076+0000] {snowflake_utilz.py:35} INFO - connection is closed
[2025-03-11T18:30:03.077+0000] {connection.py:810} INFO - closed
[2025-03-11T18:30:03.152+0000] {connection.py:816} INFO - No async queries seem to be running, deleting session
[2025-03-11T18:30:03.233+0000] {snowflake_utilz.py:38} INFO - SQLAlchemy engine disposed
[2025-03-11T18:30:03.233+0000] {python.py:237} INFO - Done. Returned value was: None
[2025-03-11T18:30:03.234+0000] {taskinstance.py:441} INFO - ::group::Post task execution logs
[2025-03-11T18:30:03.245+0000] {taskinstance.py:1205} INFO - Marking task as SUCCESS. dag_id=sales_pipeline, task_id=test_snowflake_connection, execution_date=20250311T181500, start_date=20250311T183001, end_date=20250311T183003
[2025-03-11T18:30:03.299+0000] {local_task_job_runner.py:240} INFO - Task exited with return code 0
[2025-03-11T18:30:03.332+0000] {taskinstance.py:3482} INFO - 2 downstream tasks scheduled from follow-on schedule check
[2025-03-11T18:30:03.333+0000] {local_task_job_runner.py:222} INFO - ::endgroup::
